<?xml version="1.0" encoding="utf-8"?>
<!-- This URDF was automatically created by SolidWorks to URDF Exporter! Originally created by Stephen Brawner (brawner@gmail.com) 
     Commit Version: 1.6.0-4-g7f85cfe  Build Version: 1.6.7995.38578
     For more information, please see http://wiki.ros.org/sw_urdf_exporter -->
<robot
  name="reddog">
  <link
    name="base_link">
    <inertial>
          <origin
            xyz="-0.00032 -0.00003 0.00386"
            rpy="0 0 0" />
          <mass
            value="2.38753" />
          <inertia
            ixx="0.00650389501"
            ixy="-0.00000179287"
            ixz="-0.00001597051"
            iyy="0.02042876948"
            iyz="-0.00000267819"
            izz="0.02487682627" />
    </inertial>
    <visual>
      <origin
        xyz="0 0 0"
        rpy="0 0 0" />
      <geometry>
        <mesh
          filename="package://reddog/meshes/base_link.STL" />
      </geometry>
      <material
        name="">
        <color
          rgba="0.752941176470588 0.752941176470588 0.752941176470588 1" />
      </material>
    </visual>
    <collision>
      <origin
        xyz="0 0 0"
        rpy="0 0 0" />
      <geometry>
        <mesh
          filename="package://reddog/meshes/base_link.STL" />
      </geometry>
    </collision>
  </link>
  <link
    name="fr_Link">
    <inertial>
          <origin
            xyz="0.03750 -0.01393 0.00000"
            rpy="0 0 0" />
          <mass
            value="0.32473" />
          <inertia
            ixx="0.00018594841"
            ixy="-0.00017461361"
            ixz="0.00000006110"
            iyy="0.00059635539"
            iyz="-0.00000050"
            izz="0.00064977942" />
    </inertial>
    <visual>
      <origin
        xyz="0 0 0"
        rpy="0 0 0" />
      <geometry>
        <mesh
          filename="package://reddog/meshes/fr_Link.STL" />
      </geometry>
      <material
        name="">
        <color
          rgba="0.752941176470588 0.752941176470588 0.752941176470588 1" />
      </material>
    </visual>
    <collision>
      <origin
        xyz="0 0 0"
        rpy="0 0 0" />
      <geometry>
        <mesh
          filename="package://reddog/meshes/fr_Link.STL" />
      </geometry>
    </collision>
  </link>
  <joint
    name="fr_hx"
    type="revolute">
    <origin
      xyz="0.127999974999998 -0.055 0"
      rpy="0 0 0" />
    <parent
      link="base_link" />
    <child
      link="fr_Link" />
    <axis
      xyz="1 0 0" />
    <limit
      lower="-0.57"
      upper="0.3"
      effort="0.0"
      velocity="0.0" />
  </joint>
  <link
    name="fru_Link">
    <inertial>
          <origin
            xyz="-0.00008 -0.02579 -0.12125"
            rpy="0 0 0" />
          <mass
            value="0.35357" />
          <inertia
            ixx="0.00585231191"
            ixy="0.00000025151"
            ixz="0.00000408681"
            iyy="0.00562421074"
            iyz="0.00116263343"
            izz="0.00037614865" />
    </inertial>
    <visual>
      <origin
        xyz="0 0 0"
        rpy="0 0 0" />
      <geometry>
        <mesh
          filename="package://reddog/meshes/fru_Link.STL" />
      </geometry>
      <material
        name="">
        <color
          rgba="0.752941176470588 0.752941176470588 0.752941176470588 1" />
      </material>
    </visual>
    <collision>
      <origin
        xyz="0 0 0"
        rpy="0 0 0" />
      <geometry>
        <mesh
          filename="package://reddog/meshes/fru_Link.STL" />
      </geometry>
    </collision>
  </link>
  <joint
    name="fr_hy"
    type="revolute">
    <origin
      xyz="0.0385000250000002 -0.0374999999999999 0"
      rpy="0 0 0" />
    <parent
      link="fr_Link" />
    <child
      link="fru_Link" />
    <axis
      xyz="0 1 0" />
    <limit
      lower="0.0"
      upper="2.0"
      effort="0.0"
      velocity="0.0" />
  </joint>
  <link
    name="frd_Link">
    <inertial>
          <origin
            xyz="-0.00008 -0.01547 -0.06209"
            rpy="0 0 0" />
          <mass
            value="0.04392" />
          <inertia
            ixx="0.00030707961"
            ixy="0.00000004562"
            ixz="-0.00000019131"
            iyy="0.00030314926"
            iyz="0.00004068535"
            izz="0.00001923951" />
    </inertial>
    <visual>
      <origin
        xyz="0 0 0"
        rpy="0 0 0" />
      <geometry>
        <mesh
          filename="package://reddog/meshes/frd_Link.STL" />
      </geometry>
      <material
        name="">
        <color
          rgba="0.752941176470588 0.752941176470588 0.752941176470588 1" />
      </material>
    </visual>
    <collision>
      <origin
        xyz="0 0 0"
        rpy="0 0 0" />
      <geometry>
        <mesh
          filename="package://reddog/meshes/frd_Link.STL" />
      </geometry>
    </collision>
  </link>
  <joint
    name="fr_kn"
    type="revolute">
    <origin
      xyz="0 -0.0351874453282875 -0.129999999999999"
      rpy="0 0 0" />
    <parent
      link="fru_Link" />
    <child
      link="frd_Link" />
    <axis
      xyz="0 1 0" />
    <limit
      lower="-2.0"
      upper="0.0"
      effort="0.0"
      velocity="0.0" />
  </joint>
  <link
    name="fl_Link">
    <inertial>
          <origin
            xyz="0.03750 0.01393 0.00000"
            rpy="0 0 0" />
          <mass
            value="0.32473" />
          <inertia
            ixx="0.00018594986"
            ixy="0.00017461373"
            ixz="0.00000006201"
            iyy="0.00059635638"
            iyz="0.00000060"
            izz="0.00064977963" />
    </inertial>
    <visual>
      <origin
        xyz="0 0 0"
        rpy="0 0 0" />
      <geometry>
        <mesh
          filename="package://reddog/meshes/fl_Link.STL" />
      </geometry>
      <material
        name="">
        <color
          rgba="0.752941176470588 0.752941176470588 0.752941176470588 1" />
      </material>
    </visual>
    <collision>
      <origin
        xyz="0 0 0"
        rpy="0 0 0" />
      <geometry>
        <mesh
          filename="package://reddog/meshes/fl_Link.STL" />
      </geometry>
    </collision>
  </link>
  <joint
    name="fl_hx"
    type="revolute">
    <origin
      xyz="0.127999974999998 0.055 0"
      rpy="0 0 0" />
    <parent
      link="base_link" />
    <child
      link="fl_Link" />
    <axis
      xyz="1 0 0" />
    <limit
      lower="-0.3"
      upper="0.57"
      effort="0.0"
      velocity="0.0" />
  </joint>
  <link
    name="flu_Link">
    <inertial>
          <origin
            xyz="-0.00008 0.02578 -0.12122"
            rpy="0 0 0" />
          <mass
            value="0.35375" />
          <inertia
            ixx="0.00585364661"
            ixy="-0.00000025142"
            ixz="0.00000408664"
            iyy="0.00562556977"
            iyz="-0.00116270971"
            izz="0.00037619708" />
    </inertial>
    <visual>
      <origin
        xyz="0 0 0"
        rpy="0 0 0" />
      <geometry>
        <mesh
          filename="package://reddog/meshes/flu_Link.STL" />
      </geometry>
      <material
        name="">
        <color
          rgba="0.752941176470588 0.752941176470588 0.752941176470588 1" />
      </material>
    </visual>
    <collision>
      <origin
        xyz="0 0 0"
        rpy="0 0 0" />
      <geometry>
        <mesh
          filename="package://reddog/meshes/flu_Link.STL" />
      </geometry>
    </collision>
  </link>
  <joint
    name="fl_hy"
    type="revolute">
    <origin
      xyz="0.038500025 0.0375 0"
      rpy="0 0 0" />
    <parent
      link="fl_Link" />
    <child
      link="flu_Link" />
    <axis
      xyz="0 1 0" />
    <limit
      lower="0.0"
      upper="2.0"
      effort="0.0"
      velocity="0.0" />
  </joint>
  <link
    name="fld_Link">
    <inertial>
          <origin
            xyz="-0.00008 0.01548 -0.06210"
            rpy="0 0 0" />
          <mass
            value="0.04392" />
          <inertia
            ixx="0.00030708477"
            ixy="-0.00000004533"
            ixz="-0.00000019020"
            iyy="0.00030314783"
            iyz="-0.00004068575"
            izz="0.00001923376" />
    </inertial>
    <visual>
      <origin
        xyz="0 0 0"
        rpy="0 0 0" />
      <geometry>
        <mesh
          filename="package://reddog/meshes/fld_Link.STL" />
      </geometry>
      <material
        name="">
        <color
          rgba="0.752941176470588 0.752941176470588 0.752941176470588 1" />
      </material>
    </visual>
    <collision>
      <origin
        xyz="0 0 0"
        rpy="0 0 0" />
      <geometry>
        <mesh
          filename="package://reddog/meshes/fld_Link.STL" />
      </geometry>
    </collision>
  </link>
  <joint
    name="fl_kn"
    type="revolute">
    <origin
      xyz="0 0.0351874453282872 -0.13"
      rpy="0 0 0" />
    <parent
      link="flu_Link" />
    <child
      link="fld_Link" />
    <axis
      xyz="0 1 0" />
    <limit
      lower="-2.0"
      upper="0.0"
      effort="0.0"
      velocity="0.0" />
  </joint>
  <link
    name="bl_Link">
    <inertial>
          <origin
            xyz="-0.03750 0.01393 0.00000"
            rpy="0 0 0" />
          <mass
            value="0.32473" />
          <inertia
            ixx="0.00018594992"
            ixy="-0.00017461371"
            ixz="0.00000006091"
            iyy="0.00059635632"
            iyz="-0.00000063"
            izz="0.00064977952" />
    </inertial>
    <visual>
      <origin
        xyz="0 0 0"
        rpy="0 0 0" />
      <geometry>
        <mesh
          filename="package://reddog/meshes/bl_Link.STL" />
      </geometry>
      <material
        name="">
        <color
          rgba="0.752941176470588 0.752941176470588 0.752941176470588 1" />
      </material>
    </visual>
    <collision>
      <origin
        xyz="0 0 0"
        rpy="0 0 0" />
      <geometry>
        <mesh
          filename="package://reddog/meshes/bl_Link.STL" />
      </geometry>
    </collision>
  </link>
  <joint
    name="hl_hx"
    type="revolute">
    <origin
      xyz="-0.127999975000005 0.055000000000013 0"
      rpy="0 0 0" />
    <parent
      link="base_link" />
    <child
      link="bl_Link" />
    <axis
      xyz="1 0 0" />
    <limit
      lower="-0.3"
      upper="0.57"
      effort="0.0"
      velocity="0.0" />
  </joint>
  <link
    name="blu_Link">
    <inertial>
          <origin
            xyz="-0.00008 0.02579 -0.12125"
            rpy="0 0 0" />
          <mass
            value="0.35357" />
          <inertia
            ixx="0.00585226080"
            ixy="-0.00000025114"
            ixz="0.00000408350"
            iyy="0.00562415402"
            iyz="-0.00116263019"
            izz="0.00037614383" />
    </inertial>
    <visual>
      <origin
        xyz="0 0 0"
        rpy="0 0 0" />
      <geometry>
        <mesh
          filename="package://reddog/meshes/blu_Link.STL" />
      </geometry>
      <material
        name="">
        <color
          rgba="0.752941176470588 0.752941176470588 0.752941176470588 1" />
      </material>
    </visual>
    <collision>
      <origin
        xyz="0 0 0"
        rpy="0 0 0" />
      <geometry>
        <mesh
          filename="package://reddog/meshes/blu_Link.STL" />
      </geometry>
    </collision>
  </link>
  <joint
    name="hl_hy"
    type="revolute">
    <origin
      xyz="-0.038500024999994 0.0374999999999811 0"
      rpy="0 0 0" />
    <parent
      link="bl_Link" />
    <child
      link="blu_Link" />
    <axis
      xyz="0 1 0" />
    <limit
      lower="-2.0"
      upper="0.0"
      effort="0.0"
      velocity="0.0" />
  </joint>
  <link
    name="bld_Link">
    <inertial>
          <origin
            xyz="-0.00008 0.01548 -0.06210"
            rpy="0 0 0" />
          <mass
            value="0.04392" />
          <inertia
            ixx="0.00030708477"
            ixy="-0.00000004533"
            ixz="-0.00000019020"
            iyy="0.00030314783"
            iyz="-0.00004068575"
            izz="0.00001923376" />
    </inertial>
    <visual>
      <origin
        xyz="0 0 0"
        rpy="0 0 0" />
      <geometry>
        <mesh
          filename="package://reddog/meshes/bld_Link.STL" />
      </geometry>
      <material
        name="">
        <color
          rgba="0.752941176470588 0.752941176470588 0.752941176470588 1" />
      </material>
    </visual>
    <collision>
      <origin
        xyz="0 0 0"
        rpy="0 0 0" />
      <geometry>
        <mesh
          filename="package://reddog/meshes/bld_Link.STL" />
      </geometry>
    </collision>
  </link>
  <joint
    name="hl_kn"
    type="revolute">
    <origin
      xyz="0 0.0351874453282818 -0.130000000000005"
      rpy="0 0 0" />
    <parent
      link="blu_Link" />
    <child
      link="bld_Link" />
    <axis
      xyz="0 1 0" />
    <limit
      lower="0.0"
      upper="2.0"
      effort="0.0"
      velocity="0.0" />
  </joint>
  <link
    name="br_Link">
    <inertial>
          <origin
            xyz="-0.03750 -0.01393 0.00000"
            rpy="0 0 0" />
          <mass
            value="0.32473" />
          <inertia
            ixx="0.00018594880"
            ixy="0.00017461355"
            ixz="0.00000006005"
            iyy="0.00059635526"
            iyz="0.00000057"
            izz="0.00064977890" />
    </inertial>
    <visual>
      <origin
        xyz="0 0 0"
        rpy="0 0 0" />
      <geometry>
        <mesh
          filename="package://reddog/meshes/br_Link.STL" />
      </geometry>
      <material
        name="">
        <color
          rgba="0.752941176470588 0.752941176470588 0.752941176470588 1" />
      </material>
    </visual>
    <collision>
      <origin
        xyz="0 0 0"
        rpy="0 0 0" />
      <geometry>
        <mesh
          filename="package://reddog/meshes/br_Link.STL" />
      </geometry>
    </collision>
  </link>
  <joint
    name="hr_hx"
    type="revolute">
    <origin
      xyz="-0.127999975000003 -0.0549999999999869 0"
      rpy="0 0 0" />
    <parent
      link="base_link" />
    <child
      link="br_Link" />
    <axis
      xyz="1 0 0" />
    <limit
      lower="-0.57"
      upper="0.3"
      effort="0.0"
      velocity="0.0" />
  </joint>
  <link
    name="bru_Link">
    <inertial>
          <origin
            xyz="-0.00008 -0.02579 -0.12125"
            rpy="0 0 0" />
          <mass
            value="0.35357" />
          <inertia
            ixx="0.00585231130"
            ixy="0.00000025136"
            ixz="0.00000408643"
            iyy="0.00562421013"
            iyz="0.00116263332"
            izz="0.00037614865" />
    </inertial>
    <visual>
      <origin
        xyz="0 0 0"
        rpy="0 0 0" />
      <geometry>
        <mesh
          filename="package://reddog/meshes/bru_Link.STL" />
      </geometry>
      <material
        name="">
        <color
          rgba="0.752941176470588 0.752941176470588 0.752941176470588 1" />
      </material>
    </visual>
    <collision>
      <origin
        xyz="0 0 0"
        rpy="0 0 0" />
      <geometry>
        <mesh
          filename="package://reddog/meshes/bru_Link.STL" />
      </geometry>
    </collision>
  </link>
  <joint
    name="hr_hy"
    type="revolute">
    <origin
      xyz="-0.0385000250000004 -0.0375000000000083 0"
      rpy="0 0 0" />
    <parent
      link="br_Link" />
    <child
      link="bru_Link" />
    <axis
      xyz="0 1 0" />
    <limit
      lower="-2.0"
      upper="0.0"
      effort="0.0"
      velocity="0.0" />
  </joint>
  <link
    name="brd_Link">
    <inertial>
          <origin
            xyz="-0.00008 -0.01547 -0.06209"
            rpy="0 0 0" />
          <mass
            value="0.04392" />
          <inertia
            ixx="0.00030707961"
            ixy="0.00000004562"
            ixz="-0.00000019131"
            iyy="0.00030314926"
            iyz="0.00004068535"
            izz="0.00001923951" />
    </inertial>
    <visual>
      <origin
        xyz="0 0 0"
        rpy="0 0 0" />
      <geometry>
        <mesh
          filename="package://reddog/meshes/brd_Link.STL" />
      </geometry>
      <material
        name="">
        <color
          rgba="0.752941176470588 0.752941176470588 0.752941176470588 1" />
      </material>
    </visual>
    <collision>
      <origin
        xyz="0 0 0"
        rpy="0 0 0" />
      <geometry>
        <mesh
          filename="package://reddog/meshes/brd_Link.STL" />
      </geometry>
    </collision>
  </link>
  <joint
    name="hr_kn"
    type="revolute">
    <origin
      xyz="0 -0.0351874453282743 -0.130000000000005"
      rpy="0 0 0" />
    <parent
      link="bru_Link" />
    <child
      link="brd_Link" />
    <axis
      xyz="0 1 0" />
    <limit
      lower="0.0"
      upper="2.0"
      effort="0.0"
      velocity="0.0" />
  </joint>
</robot>
